2025-05-20 23:27:22,496 - ClientTaskWorker - ERROR - do_one_task execute exception: RuntimeError: cannot sync with server Runner after 60.0 seconds
2025-05-20 23:27:22,496 - root - ERROR - Traceback (most recent call last):
  File "/home/kevinfarhat/.local/lib/python3.10/site-packages/nvflare/private/fed/app/simulator/simulator_worker.py", line 87, in do_one_task
    self.create_client_runner(client)
  File "/home/kevinfarhat/.local/lib/python3.10/site-packages/nvflare/private/fed/app/simulator/simulator_worker.py", line 78, in create_client_runner
    client_runner.init_run(app_client_root, args)
  File "/home/kevinfarhat/.local/lib/python3.10/site-packages/nvflare/private/fed/client/client_runner.py", line 666, in init_run
    raise RuntimeError(f"cannot sync with {target} Runner after {max_sync_timeout} seconds")
RuntimeError: cannot sync with server Runner after 60.0 seconds

